import { useState } from 'react';
import axios, { AxiosError } from 'axios';
import axiosInstance from '../../misch/Axios';
import { useAppDispatch } from '../../misch/Store';
import { logout } from '../../misch/store/authSlice';

const useDeleteUser = () => {
  const [loading, setLoading] = useState<boolean>(false);
  const [error, setError] = useState<string | null>(null);
  const [success, setSuccess] = useState<boolean>(false);
  const dispatch = useAppDispatch();

  const deleteUser = async (userId: number) => {
    setLoading(true);
    setError(null);
    setSuccess(false);

    try {
      await axiosInstance.delete(`/user/${userId}`);
      setSuccess(true);
      return true;
    } catch (err) {
      if (axios.isAxiosError(err)) {
        const error = err as AxiosError;
        if (error.code === 'ERR_NETWORK') {
          setError("Network error: Unable to connect to the server");
        } else if (error.response) {
          switch (error.response.status) {
            case 401:
              setError("Unauthorized: Please log in again");
              dispatch(logout());
              break;
            case 404:
              setError(`User with ID ${userId} not found`);
              break;
            case 500:
              setError("Server error");
              break;
            default:
              setError(`Error: ${error.response.status}`);
          }
        }
      } else {
        setError("An unexpected error occurred");
      }
      return false;
    } finally {
      setLoading(false);
    }
  };

  return { deleteUser, loading, error, success };
};

export default useDeleteUser;